<?xml version='1.0'?>
<sdf version='1.4'>
 <world name="default">
    <!-- Ground Plane -->
    <include>
      <uri>model://ground_plane</uri>
    </include>
    <include>
      <uri>model://sun</uri>
    </include>

  <model name="my_robot">
  <static>false</static>
<link name='Base'>
            <pose>0 0 .0195 0 0 0</pose>
	<inertial>
        <mass>300.0</mass>
        <pose>0 0 0 0 0 0</pose>
        <inertia>
          <ixx>0.5</ixx>
          <iyy>1.0</iyy>
          <izz>0.1</izz>
        </inertia>
      </inertial>
       <collision name='collision'>
              <geometry>
                <box>
                  <size>.11 .11 .039</size>
                </box>
              </geometry>
            </collision>

    <visual name='visual'>
              <geometry>
                <box>
                  <size>.11 .11 .039</size>
                </box>
              </geometry>
            </visual>
	</link>
  <link name="First_joint">
        <pose>0 0 0.0495 0 0 0</pose>
        <collision name="collision">
          <geometry>
            <cylinder>
              <radius>.05</radius>
              <length>.001</length>
            </cylinder>
          </geometry>
        </collision>
        <visual name="visual">
          <geometry>
            <cylinder>
              <radius>.05</radius>
              <length>.001</length>
            </cylinder>
          </geometry>
        </visual>

	
	<collision name="collision2">
	<pose>0 0 0.0255 0 0 0</pose>
          <geometry>
            <box>
              <size>.1 .031 .05</size>
           </box>
           </geometry>
         </collision>
        <visual name="visual2">
	<pose>0 0 0.0255 0 0 0</pose>
          <geometry>
                <box>
                  <size>.1 .031 .05</size>
                </box>
              </geometry>
            </visual>

	<collision name="collision3">
	<pose>0 0.0346 0.060 0.5236 0 0</pose>
          <geometry>
            <box>
              <size>.1 .085 .031</size>
           </box>
           </geometry>
         </collision>
        <visual name="visual3">
	<pose>0 0.0346 0.060 0.5236 0 0</pose>
          <geometry>
                <box>
                  <size>.1 .085 .031</size>
                </box>
              </geometry>
            </visual>
      </link>

<link name='Second_joint'>
         <pose>0 0.0692 0.1295 0 0 0</pose>
        <collision name="collision">
	<pose>-0.052 0 0 0 1.507 0</pose>
          <geometry>
            <cylinder>
              <radius>.03</radius>
              <length>.001</length>
            </cylinder>
          </geometry>
        </collision>
        <visual name="visual">
	<pose>-0.052 0 0 0 1.507 0</pose>
          <geometry>
            <cylinder>
              <radius>.03</radius>
              <length>.001</length>
            </cylinder>
          </geometry>
        </visual> 
 	<collision name="collision2">
	<pose>0.052 0.0 0 0 1.507 0</pose>
          <geometry>
            <cylinder>
              <radius>.03</radius>
              <length>.001</length>
            </cylinder>
          </geometry>
        </collision>
        <visual name="visual2">
	<pose>0.052 0.0 0.0 0 1.507 0</pose>
          <geometry>
            <cylinder>
              <radius>.03</radius>
              <length>.001</length>
            </cylinder>
          </geometry>
        </visual> 
       <collision name="collision3">
	<pose>0.0 0.0692 0.0395 0.5236 0 0</pose> 	 
	<geometry>
            <box>
              <size>.1 .104 .031</size>
           </box>
           </geometry>
         </collision>
        <visual name="visual3">
         <pose>0.0 0.0692 0.0395 0.5236 0 0</pose>
          <geometry>
                <box>
                  <size>.1 .104 .031</size>
                </box>
              </geometry>
            </visual>
       <collision name="collision4">
	<pose>-0.052 0.1384 0.079 0 1.507 0</pose>
          <geometry>
            <cylinder>
              <radius>.03</radius>
              <length>.001</length>
            </cylinder>
          </geometry>
        </collision>
        <visual name="visual4">
	<pose>-0.052 0.1384 0.079 0 1.507 0</pose>
          <geometry>
            <cylinder>
              <radius>.03</radius>
              <length>.001</length>
            </cylinder>
          </geometry>
        </visual> 
       <collision name="collision5">
	<pose>0.052 0.1384 0.079 0 1.507 0</pose>
          <geometry>
            <cylinder>
              <radius>.03</radius>
              <length>.001</length>
            </cylinder>
          </geometry>
        </collision>
        <visual name="visual5">
	<pose>0.052 0.1384 0.079 0 1.507 0</pose>
          <geometry>
            <cylinder>
              <radius>.03</radius>
              <length>.001</length>
            </cylinder>
          </geometry>
        </visual> 
      </link>
   <link name='Third_joint'>
            <pose>0 0.2400 0.2273 0.5236 0 0</pose>

            <collision name='collision'>
		<pose>0 0 0 0 0 0</pose>
              <geometry>
                <box>
                  <size>.1 .075 .031</size>
                </box>
              </geometry>
            </collision>

            <visual name='visual'>
             <pose>0 0 0 0 0 0</pose>
              <geometry>
                <box>
                  <size>.1 .075 .031</size>
                </box>
              </geometry>
            </visual>
          <collision name='collision2'>
		<pose>0 0.025 0 0 0 0</pose>
              <geometry>
                <box>
                  <size>.031 .031 .051</size>
                </box>
              </geometry>
            </collision>

            <visual name='visual2'>
             <pose>0 0.025 0 0 0 0</pose>
              <geometry>
                <box>
                  <size>.031 .031 .061</size>
                </box>
              </geometry>
            </visual>
      </link>
  <link name='Fourth_joint'>
         <pose>0 0.2778 0.2435 0 0 0</pose>

        <collision name="collision">
          <pose>0 0.01 -0.017 -1.0472 0 0</pose>
          <geometry>
            <cylinder>
              <radius>.015</radius>
              <length>.001</length>
            </cylinder>
          </geometry>
        </collision>
        <visual name="visual">
          <pose>0 0.01 -0.017 -1.0472 0 0</pose>
          <geometry>
            <cylinder>
              <radius>.015</radius>
              <length>.001</length>
            </cylinder>
          </geometry>
         </visual> 
            <collision name='collision2'>
	     <pose>0 0.035 -0.003 0.5236 0 0</pose>
              <geometry>
                <box>
                  <size>.1 .055 .0325</size>
                </box>
              </geometry>
            </collision>

            <visual name='visual2'>
              <pose>0 0.035 -0.003 0.5236 0 0</pose>              
               <geometry>
                <box>
                  <size>.1 .055 .025</size>
                </box>
              </geometry>
            </visual>
	</link> 

    <link name='Finger_left'>
         <pose>0 0.3778 0.2435 0 0 0</pose>

        <collision name="collision">
          <pose>0.0315 -0.01 0.035 -1.0471 0 -0.5236</pose>
          <geometry>
            <cylinder>
              <radius>.0015</radius>
              <length>.07</length>
            </cylinder>
          </geometry>
        </collision>
        <visual name="visual">
          <pose>0.0315 -0.01 0.035 -1.0471 0 -0.5236</pose>
          <geometry>
            <cylinder>
              <radius>.0045</radius>
              <length>.07</length>
            </cylinder>
          </geometry>
         </visual> 
         <collision name="collision2">
          <pose>0.0315 0.0486 0.073 -1.0471 0 0.5236</pose>
          <geometry>
            <cylinder>
              <radius>.0015</radius>
              <length>.07</length>
            </cylinder>
          </geometry>
        </collision>
        <visual name="visual2">
          <pose>0.0315 0.0486 0.073 -1.0471 0 0.5236</pose>
          <geometry>
            <cylinder>
              <radius>.0045</radius>
              <length>.07</length>
            </cylinder>
          </geometry>
         </visual> 
	</link> 
     <link name='Finger_right'>
         <pose>0 0.3778 0.2435 0 0 0</pose>

        <collision name="collision">
          <pose>-0.0315 -0.01 0.035 -1.0471 0 0.5236</pose>
          <geometry>
            <cylinder>
              <radius>.0015</radius>
              <length>.07</length>
            </cylinder>
          </geometry>
        </collision>
        <visual name="visual">
          <pose>-0.0315 -0.01 0.035 -1.0471 0 0.5236</pose>
          <geometry>
            <cylinder>
              <radius>.0045</radius>
              <length>.07</length>
            </cylinder>
          </geometry>
         </visual> 
         <collision name="collision2">
          <pose>-0.0315 0.0486 0.073 -1.0471 0 -0.5236</pose>
          <geometry>
            <cylinder>
              <radius>.0015</radius>
              <length>.07</length>
            </cylinder>
          </geometry>
        </collision>
        <visual name="visual2">
          <pose>-0.0315 0.0486 0.073 -1.0471 0 -0.5236</pose>
          <geometry>
            <cylinder>
              <radius>.0045</radius>
              <length>.07</length>
            </cylinder>
          </geometry>
         </visual> 
	</link> 

      <joint type="revolute" name="base_hinge">
        <pose>0 0 0.05 0 0 0</pose>
        <child>First_joint</child>
        <parent>Base</parent>
        <axis>
          <xyz>0 0 1</xyz>
        </axis>
      </joint>

     <joint type="revolute" name="First_joint_hinge">
   <!--     <pose>-0.55 0.0017 0.001 0 0 0</pose> -->
         <pose>0 0 0 0 0 0</pose>
        <child>Second_joint</child>
        <parent>First_joint</parent>
        <axis>
                <limit>
                    <lower>-0.4</lower>
                    <upper>0.5</upper>
                </limit>
          <xyz>1 0 0</xyz>
        </axis>
      </joint>
    <joint type="revolute" name="Second_joint_hinge">
        <pose>0 -0.032 -0.0188 0.5236 0 0</pose>
        <child>Third_joint</child>
        <parent>Second_joint</parent>
        <axis>
                 <limit>
                    <lower>-0.4</lower>
                    <upper>0.5</upper>
                </limit>
          <xyz>1 0 0</xyz>
        </axis>
      </joint>

    <joint type="revolute" name="Third_joint_hinge">
        <pose>0 -0.02 -0.04 0.5236 0 0</pose>
        <child>Fourth_joint</child>
        <parent>Third_joint</parent>
        <axis>
          <xyz>0 1.73 1</xyz>
        </axis>
      </joint> 
      <joint type="revolute" name="right_finger_hinge">
        <pose>0 -0.05 0 0.5236 0 0</pose>
        <child>Finger_right</child>
        <parent>Fourth_joint</parent>
        <axis>
                <limit>
                    <lower>-0.4</lower>
                    <upper>0.0</upper>
                </limit>
          <xyz>0 1 -1.73</xyz>
        </axis>
      </joint> 
      <joint type="revolute" name="left_finger_hinge">
        <pose>0 -0.05 0 0.5236 0 0</pose>
        <child>Finger_left</child>
        <parent>Fourth_joint</parent>
        <axis>
               <limit>
                    <lower>0.0</lower>
                    <upper>0.4</upper>
               </limit>
          <xyz>0 1 -1.73</xyz>
        </axis>
      </joint> 
     <plugin name="SetJoints" filename="libSetJoints.so"/>
	</plugin>
  </model>
 </world>
</sdf>
